<?xml version="1.0" ?>
<!-- =================================================================================== -->
<!-- |    This document was autogenerated by xacro from /home/guang/projects/rm/gazebo_ws/src/RoboRTS-Simple-Simulator-Wrapper/RoboRTS_Gazebo/robots/infantry.xacro | -->
<!-- |    EDITING THIS FILE BY HAND IS NOT RECOMMENDED                                 | -->
<!-- =================================================================================== -->
<robot name="roborts_robot_xacro" xmlns:xacro="http://www.ros.org/wiki/xacro">
  <link name="base_link">
    <inertial>
      <origin rpy="0 0 0" xyz="0 0 0"/>
      <mass value="25.625"/>
      <inertia ixx="0.10311" ixy="-9.0391E-05" ixz="0.0071078" iyy="0.24575" iyz="2.1083E-05" izz="0.32438"/>
    </inertial>
    <collision>
      <origin rpy="0 0 0" xyz="0 0 0"/>
      <geometry>
        <box size="0.55 0.4 0.1"/>
      </geometry>
    </collision>
    <visual>
      <origin rpy="0 0 0" xyz="0 0 0"/>
      <geometry>
        <mesh filename="package://roborts_gazebo/meshes/base_link.STL"/>
      </geometry>
      <material name="">
        <color rgba="0 0 0 1"/>
      </material>
    </visual>
  </link>
  <!--<link-->
  <!--name="base_footprint">-->
  <!--<inertial>-->
  <!--<origin-->
  <!--xyz="-0.025782 0 0.025311"-->
  <!--rpy="0 0 0" />-->
  <!--<mass-->
  <!--value="25.625" />-->
  <!--<inertia-->
  <!--ixx="0.10311"-->
  <!--ixy="-9.0391E-05"-->
  <!--ixz="0.0071078"-->
  <!--iyy="0.24575"-->
  <!--iyz="2.1083E-05"-->
  <!--izz="0.32438" />-->
  <!--</inertial>-->
  <!--<collision>-->
  <!--<origin-->
  <!--xyz="0 0 0"-->
  <!--rpy="0 0 0" />-->
  <!--<geometry>-->
  <!--<box-->
  <!--size= "0.55 0.4 0.1"-->
  <!--/>-->
  <!--</geometry>-->
  <!--</collision>-->
  <!--</link>-->
  <!--<joint-->
  <!--name="base_link_to_base_foot_print"-->
  <!--type="fixed">-->
  <!--<origin-->
  <!--xyz="0 0 0"-->
  <!--rpy="0 0 0" />-->
  <!--<parent-->
  <!--link="base_link" />-->
  <!--<child-->
  <!--link="base_footprint" />-->
  <!--</joint>-->
  <link name="br_wheel_link">
    <inertial>
      <origin rpy="0 0 0" xyz="0 0.014616 0"/>
      <mass value="0.86078"/>
      <inertia ixx="0.0015361" ixy="1.6456E-06" ixz="-2.0131E-06" iyy="0.002844" iyz="-9.5351E-07" izz="0.0015337"/>
    </inertial>
    <visual>
      <origin rpy="0 0 0" xyz="0 0 0"/>
      <geometry>
        <mesh filename="package://roborts_gazebo/meshes/br_wheel_link.STL"/>
      </geometry>
      <material name="roborts_red">
        <color rgba="0.949019607843 0.149019607843 0.0745098039216 1"/>
      </material>
    </visual>
    <collision>
      <origin rpy="1.5708 0 0" xyz="0 0 0"/>
      <geometry>
        <cylinder length="0.02" radius="0.078"/>
      </geometry>
      <surface>
        <friction>
          <ode>
            <mu>0.0</mu>
            <mu2>0.0</mu2>
          </ode>
        </friction>
      </surface>
    </collision>
  </link>
  <joint name="base_link_to_br_wheel_joint" type="continuous">
    <origin rpy="0 0 -3.1416" xyz="-0.21 -0.25 0"/>
    <parent link="base_link"/>
    <child link="br_wheel_link"/>
    <axis xyz="0 1 0"/>
  </joint>
  <link name="bl_wheel_link">
    <inertial>
      <origin rpy="0 0 0" xyz="0 -0.014551 0"/>
      <mass value="0.86078"/>
      <inertia ixx="0.0015355" ixy="4.8831E-07" ixz="1.8067E-06" iyy="0.002844" iyz="9.4618E-08" izz="0.0015338"/>
    </inertial>
    <visual>
      <origin rpy="0 0 0" xyz="0 0 0"/>
      <geometry>
        <mesh filename="package://roborts_gazebo/meshes/bl_wheel_link.STL"/>
      </geometry>
      <material name="">
        <color rgba="0.79216 0.81961 0.93333 1"/>
      </material>
    </visual>
    <collision>
      <origin rpy="-1.5708 0 0" xyz="0 0 0"/>
      <geometry>
        <cylinder length="0.02" radius="0.078"/>
      </geometry>
      <surface>
        <friction>
          <ode>
            <mu>0.0</mu>
            <mu2>0.0</mu2>
          </ode>
        </friction>
      </surface>
    </collision>
  </link>
  <joint name="base_link_to_bl_wheel_joint" type="continuous">
    <origin rpy="0 0 -3.1416" xyz="-0.21 0.25 0"/>
    <parent link="base_link"/>
    <child link="bl_wheel_link"/>
    <axis xyz="0 -1 0"/>
  </joint>
  <link name="fl_wheel_link">
    <inertial>
      <origin rpy="0 0 0" xyz="0 -0.014549 0"/>
      <mass value="0.86078"/>
      <inertia ixx="0.0015361" ixy="1.6481E-06" ixz="-2.0131E-06" iyy="0.002844" iyz="-9.4912E-07" izz="0.0015338"/>
    </inertial>
    <visual>
      <origin rpy="0 0 0" xyz="0 0 0"/>
      <geometry>
        <mesh filename="package://roborts_gazebo/meshes/fl_wheel_link.STL"/>
      </geometry>
      <material name="">
        <color rgba="0.79216 0.81961 0.93333 1"/>
      </material>
    </visual>
    <collision>
      <origin rpy="-1.5708 0 0" xyz="0 0 0"/>
      <geometry>
        <cylinder length="0.02" radius="0.078"/>
      </geometry>
      <surface>
        <friction>
          <ode>
            <mu>0.0</mu>
            <mu2>0.0</mu2>
          </ode>
        </friction>
      </surface>
    </collision>
  </link>
  <joint name="base_link_to_fl_wheel_joint" type="continuous">
    <origin rpy="0 0 3.1416" xyz="0.21 0.25 0"/>
    <parent link="base_link"/>
    <child link="fl_wheel_link"/>
    <axis xyz="0 1 0"/>
  </joint>
  <link name="fr_wheel_link">
    <inertial>
      <origin rpy="0 0 0" xyz="0.00010086 0.014592 0"/>
      <mass value="0.86078"/>
      <inertia ixx="0.0015355" ixy="5.3543E-07" ixz="1.8067E-06" iyy="0.002844" iyz="1.1717E-07" izz="0.0015337"/>
    </inertial>
    <visual>
      <origin rpy="0 0 0" xyz="0 0 0"/>
      <geometry>
        <mesh filename="package://roborts_gazebo/meshes/fr_wheel_link.STL"/>
      </geometry>
      <material name="">
        <color rgba="0.75294 0.75294 0.75294 1"/>
      </material>
    </visual>
    <collision>
      <origin rpy="1.5708 0 0" xyz="0 0 0"/>
      <geometry>
        <cylinder length="0.02" radius="0.078"/>
      </geometry>
      <surface>
        <friction>
          <ode>
            <mu>0.0</mu>
            <mu2>0.0</mu2>
          </ode>
        </friction>
      </surface>
    </collision>
  </link>
  <joint name="base_link_to_fr_wheel_joint" type="continuous">
    <origin rpy="0 0 -3.1416" xyz="0.21 -0.25 0"/>
    <parent link="base_link"/>
    <child link="fr_wheel_link"/>
    <axis xyz="0 -1 0"/>
  </joint>
  <link name="yaw_link">
    <inertial>
      <origin rpy="0 0 0" xyz="0 0.024936 0"/>
      <mass value="0.98307"/>
      <inertia ixx="0.0072228" ixy="1.8624E-07" ixz="5.1373E-07" iyy="0.0035103" iyz="-0.0016193" izz="0.00443"/>
    </inertial>
    <visual>
      <origin rpy="0 0 0" xyz="0 0 0"/>
      <geometry>
        <mesh filename="package://roborts_gazebo/meshes/yaw_link.STL"/>
      </geometry>
      <material name="">
        <color rgba="0.89412 0.91373 0.92941 1"/>
      </material>
    </visual>
    <collision>
      <origin rpy="0 0 0" xyz="0 0 1"/>
      <geometry>
        <box size="0.01 0.01 0.01"/>
      </geometry>
    </collision>
  </link>
  <joint name="base_link_to_yaw_joint" type="fixed">
    <origin rpy="0 0 0" xyz="-0.017561 0 0.1342"/>
    <parent link="base_link"/>
    <child link="yaw_link"/>
    <axis xyz="0 0 1"/>
    <!--<limit-->
    <!--lower="-1.57"-->
    <!--upper="1.57"-->
    <!--effort="1000"-->
    <!--velocity="100" />-->
  </joint>
  <link name="pitch_link">
    <inertial>
      <origin rpy="0 0 0" xyz="-0.0024244 0.00051587 -0.011372"/>
      <mass value="0.68228"/>
      <inertia ixx="0.0019856" ixy="5.1373E-05" ixz="0.00087772" iyy="0.0042744" iyz="-2.4468E-05" izz="0.0037072"/>
    </inertial>
    <visual>
      <origin rpy="0 0 0" xyz="0 0 0"/>
      <geometry>
        <mesh filename="package://roborts_gazebo/meshes/pitch_link.STL"/>
      </geometry>
      <material name="">
        <color rgba="1 1 1 1"/>
      </material>
    </visual>
    <collision>
      <origin rpy="0 0 0" xyz="0 0 0"/>
      <geometry>
        <box size="0.01 0.01 0.01"/>
      </geometry>
    </collision>
  </link>
  <joint name="yaw_to_pitch_joint" type="revolute">
    <origin rpy="0 0 0" xyz="0 0 0.125"/>
    <parent link="yaw_link"/>
    <child link="pitch_link"/>
    <axis xyz="0 1 0"/>
    <limit effort="1000" lower="-0.001" upper="0.001" velocity="100"/>
  </joint>
  <link name="camera_link">
    <inertial>
      <origin rpy="0 0 0" xyz="0.0060861 0 0"/>
      <mass value="0.01627"/>
      <inertia ixx="3.55E-06" ixy="2.3732E-22" ixz="1.3726E-09" iyy="2.0801E-06" iyz="6.7678E-23" izz="2.0554E-06"/>
    </inertial>
    <visual>
      <origin rpy="0 0 0" xyz="0 0 0"/>
      <geometry>
        <mesh filename="package://roborts_gazebo/meshes/camera_link.STL"/>
      </geometry>
      <material name="">
        <!-- <color
          rgba="0.75294 0.75294 0.75294 1" /> -->
        <color rgba="242 38 19 1"/>
      </material>
    </visual>
    <collision>
      <origin rpy="0 0 0" xyz="0 0 0"/>
      <geometry>
        <mesh filename="package://roborts_gazebo/meshes/camera_link.STL"/>
      </geometry>
    </collision>
  </link>
  <joint name="pitch_link_to_camera_wheel_joint" type="fixed">
    <origin rpy="0 0 0" xyz="0.041 0 0.049"/>
    <parent link="pitch_link"/>
    <child link="camera_link"/>
    <axis xyz="0 0 0"/>
  </joint>
  <link name="base_laser_link">
    <inertial>
      <origin rpy="0 0 0" xyz="0 0 0"/>
      <mass value="0.12185"/>
      <inertia ixx="6.3159E-05" ixy="-9.0976E-22" ixz="-4.4573E-07" iyy="6.3776E-05" iyz="-1.8492E-21" izz="4.2072E-05"/>
    </inertial>
    <!-- <visual>
      <origin
        xyz="0 0 0"
        rpy="0 0 0" />
      <geometry>
        <mesh
          filename="package://roborts_gazebo/meshes/laser_link.STL" />
      </geometry>
      <material
        name="">
        <color
          rgba="0.75294 0.75294 0.75294 1" />
      </material>
    </visual> -->
    <!-- <collision>
      <origin
        xyz="0 0 0"
        rpy="0 0 0" />
      <geometry>
        <mesh
          filename="package://roborts_gazebo/meshes/laser_link.STL" />
      </geometry>
    </collision> -->
  </link>
  <joint name="base_link_to_laser_joint" type="fixed">
    <origin rpy="0 0 0" xyz="0 0 0.1"/>
    <parent link="base_link"/>
    <child link="base_laser_link"/>
    <axis xyz="0 0 0"/>
  </joint>
  <link name="uwb_tag_link">
    <inertial>
      <origin rpy="0 0 0" xyz="0 0 0"/>
      <mass value="0.02"/>
      <inertia ixx="6.3159E-05" ixy="-9.0976E-22" ixz="-4.4573E-07" iyy="6.3776E-05" iyz="-1.8492E-21" izz="4.2072E-05"/>
    </inertial>
    <!-- <visual>
      <origin
        xyz="0 0 0"
        rpy="0 0 0" />
      <geometry>
        <box
          size= "0.05 0.05 0.05"
        />
      </geometry>
      <material
        name="">
        <color
          rgba="0.75294 0.75294 0.75294 1" />
      </material>
    </visual> -->
    <!-- <collision>
      <origin
        xyz="0 0 0"
        rpy="0 0 0" />
      <geometry>
        <mesh
          filename="package://roborts_gazebo/meshes/laser_link.STL" />
      </geometry>
    </collision> -->
  </link>
  <joint name="base_link_to_uwb_tag_link_joint" type="fixed">
    <origin rpy="0 0 0" xyz="-0.18 0.1 0.38"/>
    <parent link="base_link"/>
    <child link="uwb_tag_link"/>
    <axis xyz="0 0 0"/>
  </joint>
  <link name="imu">
    <inertial>
      <origin rpy="0 0 0" xyz="0 0 0"/>
      <mass value="0.0001"/>
      <inertia ixx="6.3159E-25" ixy="-9.0976E-22" ixz="-4.4573E-27" iyy="6.3776E-25" iyz="-1.8492E-21" izz="4.2072E-25"/>
    </inertial>
    <visual>
      <origin rpy="0 0 0" xyz="0 0 0"/>
      <geometry>
        <box size="0.0001 0.0001 0.0001"/>
      </geometry>
      <material name="">
        <color rgba="0.75294 0.75294 0.75294 1"/>
      </material>
    </visual>
  </link>
  <joint name="uwb_tag_link_to_imu_link_joint" type="fixed">
    <origin rpy="0 0 0" xyz="0 0 0"/>
    <parent link="uwb_tag_link"/>
    <child link="imu"/>
    <axis xyz="0 0 0"/>
  </joint>
  <gazebo reference="fr_wheel_link">
    <material>Gazebo/White</material>
    <turnGravityOff>false</turnGravityOff>
  </gazebo>
  <gazebo reference="fl_wheel_link">
    <material>Gazebo/White</material>
    <turnGravityOff>false</turnGravityOff>
  </gazebo>
  <gazebo reference="br_wheel_link">
    <material>Gazebo/White</material>
    <turnGravityOff>false</turnGravityOff>
  </gazebo>
  <gazebo reference="bl_wheel_link">
    <material>Gazebo/White</material>
    <turnGravityOff>false</turnGravityOff>
  </gazebo>
  <gazebo reference="yaw_link">
    <material>Gazebo/Yellow</material>
    <turnGravityOff>false</turnGravityOff>
  </gazebo>
  <gazebo reference="pitch_link">
    <material>Gazebo/Grey</material>
    <turnGravityOff>false</turnGravityOff>
  </gazebo>
  <gazebo reference="camera_link">
    <material>Gazebo/Orange</material>
    <turnGravityOff>false</turnGravityOff>
  </gazebo>
  <!-- materials -->
  <gazebo reference="base_link">
    <material>Gazebo/Black</material>
    <turnGravityOff>false</turnGravityOff>
    <!--<kinematic>1</kinematic>-->
  </gazebo>
  <gazebo reference="uwb_tag_link">
    <material>Gazebo/Black</material>
    <turnGravityOff>false</turnGravityOff>
  </gazebo>
  <gazebo reference="base_laser_link">
    <material>Gazebo/Black</material>
    <turnGravityOff>false</turnGravityOff>
  </gazebo>
  <!-- hokuyo -->
  <gazebo reference="base_laser_link">
    <sensor name="head_hokuyo_sensor" type="ray">
      <pose>0 0 0.2 0 0 0</pose>
      <visualize>false</visualize>
      <update_rate>15</update_rate>
      <ray>
        <scan>
          <horizontal>
            <samples>720</samples>
            <resolution>0.5</resolution>
            <min_angle>-3.14159</min_angle>
            <max_angle>3.14159</max_angle>
          </horizontal>
        </scan>
        <range>
          <min>0.3</min>
          <max>4.5</max>
          <resolution>0.3</resolution>
        </range>
        <noise>
          <type>gaussian</type>
          <!-- Noise parameters based on published spec for Hokuyo laser
               achieving "+-30mm" accuracy at range < 10m.  A mean of 0.0m and
               stddev of 0.01m will put 99.7% of samples within 0.03m of the true
               reading. -->
          <mean>0.0</mean>
          <stddev>0.015</stddev>
        </noise>
      </ray>
      <plugin filename="libgazebo_ros_laser.so" name="gazebo_ros_head_hokuyo_controller">
        <topicName>scan</topicName>
        <frameName>base_laser_link</frameName>
      </plugin>
    </sensor>
  </gazebo>
  <!-- position controller plugin-->
  <gazebo>
    <plugin filename="libroborts_gazebo_ros_force_based_omni_move.so" name="mecanum_base_controller">
      <cmd_vel_topic>/cmd_vel</cmd_vel_topic>
      <odom_topic>odom</odom_topic>
      <odom_frame>odom</odom_frame>
      <odom_rate>20.0</odom_rate>
      <robot_base_frame>base_link</robot_base_frame>
      <publish_odom_tf>1</publish_odom_tf>
      <rotation_velocity_p_gain>800.0</rotation_velocity_p_gain>
    </plugin>
  </gazebo>
  <!--<gazebo>-->
  <!--<plugin name="mecanum_base_controller" filename="libroborts_gazebo_ros_force_based_move.so">-->
  <!--<commandTopic>/cmd_vel</commandTopic>-->
  <!--<odometryTopic>odom</odometryTopic>-->
  <!--<odometryFrame>odom</odometryFrame>-->
  <!--<odometryRate>20.0</odometryRate>-->
  <!--<robotBaseFrame>base_link</robotBaseFrame>-->
  <!--<yaw_velocity_p_gain>500</yaw_velocity_p_gain>-->
  <!--<x_velocity_p_gain>3000</x_velocity_p_gain>-->
  <!--<y_velocity_p_gain>3000</y_velocity_p_gain>-->
  <!--<publishOdometryTf>1</publishOdometryTf>-->
  <!--</plugin>-->
  <!--</gazebo>-->
  <gazebo>
    <plugin filename="libroborts_gazebo_ros_uwb.so" name="uwb_plugin">
      <topic_name>uwb</topic_name>
      <frame_id>uwb</frame_id>
      <body_name>base_link</body_name>
      <gaussian_noise>0.04</gaussian_noise>
      <update_rate_hz>15.0</update_rate_hz>
    </plugin>
  </gazebo>
  <gazebo reference="imu">
    <gravity>true</gravity>
    <sensor name="imu_sensor" type="imu">
      <always_on>true</always_on>
      <update_rate>50</update_rate>
      <visualize>true</visualize>
      <topic>__default_topic__</topic>
      <plugin filename="libgazebo_ros_imu_sensor.so" name="imu_plugin">
        <topicName>imu</topicName>
        <bodyName>imu</bodyName>
        <updateRateHZ>50.0</updateRateHZ>
        <gaussianNoise>0.03</gaussianNoise>
        <xyzOffset>0 0 0</xyzOffset>
        <rpyOffset>0 0 0</rpyOffset>
        <frameName>imu</frameName>
      </plugin>
      <pose>0 0 0 0 0 0</pose>
    </sensor>
  </gazebo>
  <!-- ros_control plugin -->
  <!--<gazebo>-->
  <!--<plugin name="gazebo_ros_control" filename="libgazebo_ros_control.so">-->
  <!--<robotParam>robot_description</robotParam>-->
  <!-- <robotSimType>gazebo_ros_control/DefaultRobotHWSim</robotSimType>-->
  <!--</plugin>-->
  <!--</gazebo>-->
  <!-- camera -->
  <gazebo reference="camera_link">
    <sensor name="camera1" type="camera">
      <update_rate>30.0</update_rate>
      <camera name="head">
        <horizontal_fov>1.3962634</horizontal_fov>
        <image>
          <width>800</width>
          <height>800</height>
          <format>R8G8B8</format>
        </image>
        <clip>
          <near>0.02</near>
          <far>300</far>
        </clip>
        <noise>
          <type>gaussian</type>
          <!-- Noise is sampled independently per pixel on each frame.
               That pixel's noise value is added to each of its color
               channels, which at that point lie in the range [0,1]. -->
          <mean>0.0</mean>
          <stddev>0.007</stddev>
        </noise>
      </camera>
      <plugin filename="libgazebo_ros_camera.so" name="camera_controller">
        <alwaysOn>true</alwaysOn>
        <updateRate>0.0</updateRate>
        <cameraName>camera1</cameraName>
        <imageTopicName>image_raw</imageTopicName>
        <cameraInfoTopicName>camera_info</cameraInfoTopicName>
        <frameName>camera_link_optical</frameName>
        <!-- setting hackBaseline to anything but 0.0 will cause a misalignment
            between the gazebo sensor image and the frame it is supposed to
            be attached to -->
        <hackBaseline>0.0</hackBaseline>
        <distortionK1>0.0</distortionK1>
        <distortionK2>0.0</distortionK2>
        <distortionK3>0.0</distortionK3>
        <distortionT1>0.0</distortionT1>
        <distortionT2>0.0</distortionT2>
        <CxPrime>0</CxPrime>
        <Cx>0.0</Cx>
        <Cy>0.0</Cy>
        <focalLength>0.0</focalLength>
      </plugin>
    </sensor>
  </gazebo>
  <!--<xacro:include filename="$(find roborts_gazebo)/robots/infantry.transmission.xacro" />-->
  <!-- Import Rviz colors -->
  <!-- <xacro:include filename="$(find rrbot_description)/urdf/materials.xacro" /> -->
</robot>

